Workbook
Name Slicer_customer_state: #N/A

Sheet Pivot_Delivery
A3: Share of orders | B3: Column Labels
A4: Row Labels | B4: 1 | C4: 2 | D4: 3 | E4: 3.5 | F4: 4 | G4: 4.5 | H4: 5 | I4: (blank) | J4: Grand Total
A5: Late | B5: 0.47 | C5: 0.06 | D5: 0.135 | E5: 0 | F5: 0.12 | G5: 0 | H5: 0.1875 | I5: 0.0275 | J5: 1
A6: Not Delivered | B6: 0.66666667 | C6: 0.083333333 | D6: 0.0625 | E6: 0 | F6: 0.052083333 | G6: 0 | H6: 0.052083333 | I6: 0.083333333 | J6: 1
A7: On Time | B7: 0.065053286 | C7: 0.02464476 | D7: 0.080595027 | E7: 0.00022202487 | F7: 0.19382771 | G7: 0.00044404973 | H7: 0.62966252 | I7: 0.0055506217 | J7: 1
A8: Grand Total | B8: 0.109 | C8: 0.0286 | D8: 0.0846 | E8: 0.0002 | F8: 0.1852 | G8: 0.0004 | H8: 0.5832 | I8: 0.0088 | J8: 1

Sheet Pivot_Category
A3: Row Labels | B3: Revenue | C3: Avg review
A4: watches_gifts | B4: 62277.93 | C4: 4.0361011
A5: health_beauty | B5: 57682.61 | C5: 4.1775701
A6: sports_leisure | B6: 56562.99 | C6: 4.2105263
A7: computers_accessories | B7: 54486.87 | C7: 4.0854701
A8: bed_bath_table | B8: 52471.47 | C8: 3.9265957
A9: cool_stuff | B9: 34677 | C9: 4.1290323
A10: furniture_decor | B10: 33294.32 | C10: 4.1019737
A11: auto | B11: 32574.81 | C11: 4.1
A12: housewares | B12: 28486.43 | C12: 4.1512027
A13: garden_tools | B13: 23726.55 | C13: 4.241573
A14: toys | B14: 23671.47 | C14: 4.1621622
A15: perfumery | B15: 20736.05 | C15: 4.2893082
... A71: Grand Total | B71: 708478.56 | C71: 4.1155165

Sheet Pivot_Monthly
A3: Row Labels | B3: Revenue | C3: Orders
A4: 2016-09 | B4: 72.89 | C4: 1
A5: 2016-10 | B5: 3045.15 | C5: 16
A6: 2017-01 | B6: 5249.46 | C6: 48
A7: 2017-02 | B7: 15745.44 | C7: 85
A8: 2017-03 | B8: 20527.76 | C8: 136
A9: 2017-04 | B9: 23997.95 | C9: 125
A10: 2017-05 | B10: 24362.81 | C10: 178
A11: 2017-06 | B11: 21248.01 | C11: 154
A12: 2017-07 | B12: 22834.42 | C12: 197
A13: 2017-08 | B13: 28483.18 | C13: 235
A14: 2017-09 | B14: 39166.19 | C14: 199
A15: 2017-10 | B15: 37725.04 | C15: 218
... A26: Grand Total | B26: 708478.56 | C26: 5000

Sheet KPI_Summary
A1: KPI Summary (live formulas on the Orders sheet)
A3: Total orders | B3: =COUNTA(Orders!$A$2:$A$5001) -> 5000
A4: Total revenue | B4: =SUM(Orders!$G$2:$G$5001) -> 708478.56
A5: Average order value | B5: =AVERAGE(Orders!$G$2:$G$5001) -> 141.69571
A6: Average delivery days | B6: =AVERAGE(Orders!$J$2:$J$5001) -> 12.191069
A7: Late delivery % | B7: =COUNTIF(Orders!$K$2:$K$5001,"Late")/COUNTIF(Orders!$K$2:$K$5001,"<>Not Delivered") -> 0.081566069
A8: Average review score | B8: =AVERAGE(Orders!$L$2:$L$5001) -> 4.1155165
A9: Avg review - on time | B9: =AVERAGEIFS(Orders!$L$2:$L$5001,Orders!$K$2:$K$5001,"On Time") -> 4.30643
A10: Avg review - late | B10: =AVERAGEIFS(Orders!$L$2:$L$5001,Orders!$K$2:$K$5001,"Late") -> 2.4807198
A13: State | B13: State name | C13: Orders | D13: Revenue | E13: Avg order value | F13: Late % | G13: Avg review
A14: SP | B14: =VLOOKUP(A14,State_Lookup!$A$2:$B$28,2,FALSE) -> Sao Paulo | C14: =COUNTIFS(Orders!$D$2:$D$5001,A14) -> 2072 | D14: =SUMIFS(Orders!$G$2:$G$5001,Orders!$D$2:$D$5001,A14) -> 268206.5 | E14: =IFERROR(D14/C14,0) -> 129.44329 | F14: =IFERROR(COUNTIFS(Orders!$D$2:$D$5001,A14,Orders!$K$2:$K$5001,"Late")/C14,0) -> 0.060328185 | G14: =IFERROR(AVERAGEIFS(Orders!$L$2:$L$5001,Orders!$D$2:$D$5001,A14),0) -> 4.2192214
A15: RJ | B15: =VLOOKUP(A15,State_Lookup!$A$2:$B$28,2,FALSE) -> Rio de Janeiro | C15: =COUNTIFS(Orders!$D$2:$D$5001,A15) -> 661 | D15: =SUMIFS(Orders!$G$2:$G$5001,Orders!$D$2:$D$5001,A15) -> 113982.93 | E15: =IFERROR(D15/C15,0) -> 172.44014 | F15: =IFERROR(COUNTIFS(Orders!$D$2:$D$5001,A15,Orders!$K$2:$K$5001,"Late")/C15,0) -> 0.13313162 | G15: =IFERROR(AVERAGEIFS(Orders!$L$2:$L$5001,Orders!$D$2:$D$5001,A15),0) -> 3.8993902
A16: MG | B16: =VLOOKUP(A16,State_Lookup!$A$2:$B$28,2,FALSE) -> Minas Gerais | C16: =COUNTIFS(Orders!$D$2:$D$5001,A16) -> 578 | D16: =SUMIFS(Orders!$G$2:$G$5001,Orders!$D$2:$D$5001,A16) -> 79668.42 | E16: =IFERROR(D16/C16,0) -> 137.83464 | F16: =IFERROR(COUNTIFS(Orders!$D$2:$D$5001,A16,Orders!$K$2:$K$5001,"Late")/C16,0) -> 0.053633218 | G16: =IFERROR(AVERAGEIFS(Orders!$L$2:$L$5001,Orders!$D$2:$D$5001,A16),0) -> 4.1931818
A17: RS | B17: =VLOOKUP(A17,State_Lookup!$A$2:$B$28,2,FALSE) -> Rio Grande do Sul | C17: =COUNTIFS(Orders!$D$2:$D$5001,A17) -> 274 | D17: =SUMIFS(Orders!$G$2:$G$5001,Orders!$D$2:$D$5001,A17) -> 38312.26 | E17: =IFERROR(D17/C17,0) -> 139.82577 | F17: =IFERROR(COUNTIFS(Orders!$D$2:$D$5001,A17,Orders!$K$2:$K$5001,"Late")/C17,0) -> 0.054744526 | G17: =IFERROR(AVERAGEIFS(Orders!$L$2:$L$5001,Orders!$D$2:$D$5001,A17),0) -> 4.1881919
A18: PR | B18: =VLOOKUP(A18,State_Lookup!$A$2:$B$28,2,FALSE) -> Parana | C18: =COUNTIFS(Orders!$D$2:$D$5001,A18) -> 275 | D18: =SUMIFS(Orders!$G$2:$G$5001,Orders!$D$2:$D$5001,A18) -> 34689.79 | E18: =IFERROR(D18/C18,0) -> 126.14469 | F18: =IFERROR(COUNTIFS(Orders!$D$2:$D$5001,A18,Orders!$K$2:$K$5001,"Late")/C18,0) -> 0.058181818 | G18: =IFERROR(AVERAGEIFS(Orders!$L$2:$L$5001,Orders!$D$2:$D$5001,A18),0) -> 4.0512821
A19: SC | B19: =VLOOKUP(A19,State_Lookup!$A$2:$B$28,2,FALSE) -> Santa Catarina | C19: =COUNTIFS(Orders!$D$2:$D$5001,A19) -> 206 | D19: =SUMIFS(Orders!$G$2:$G$5001,Orders!$D$2:$D$5001,A19) -> 26254.66 | E19: =IFERROR(D19/C19,0) -> 127.44981 | F19: =IFERROR(COUNTIFS(Orders!$D$2:$D$5001,A19,Orders!$K$2:$K$5001,"Late")/C19,0) -> 0.087378641 | G19: =IFERROR(AVERAGEIFS(Orders!$L$2:$L$5001,Orders!$D$2:$D$5001,A19),0) -> 4.0637255
A20: BA | B20: =VLOOKUP(A20,State_Lookup!$A$2:$B$28,2,FALSE) -> Bahia | C20: =COUNTIFS(Orders!$D$2:$D$5001,A20) -> 176 | D20: =SUMIFS(Orders!$G$2:$G$5001,Orders!$D$2:$D$5001,A20) -> 25237.68 | E20: =IFERROR(D20/C20,0) -> 143.39591 | F20: =IFERROR(COUNTIFS(Orders!$D$2:$D$5001,A20,Orders!$K$2:$K$5001,"Late")/C20,0) -> 0.14204545 | G20: =IFERROR(AVERAGEIFS(Orders!$L$2:$L$5001,Orders!$D$2:$D$5001,A20),0) -> 4.0402299
A21: ES | B21: =VLOOKUP(A21,State_Lookup!$A$2:$B$28,2,FALSE) -> Espirito Santo | C21: =COUNTIFS(Orders!$D$2:$D$5001,A21) -> 95 | D21: =SUMIFS(Orders!$G$2:$G$5001,Orders!$D$2:$D$5001,A21) -> 17825.27 | E21: =IFERROR(D21/C21,0) -> 187.63442 | F21: =IFERROR(COUNTIFS(Orders!$D$2:$D$5001,A21,Orders!$K$2:$K$5001,"Late")/C21,0) -> 0.15789474 | G21: =IFERROR(AVERAGEIFS(Orders!$L$2:$L$5001,Orders!$D$2:$D$5001,A21),0) -> 3.7446809
A22: DF | B22: =VLOOKUP(A22,State_Lookup!$A$2:$B$28,2,FALSE) -> Distrito Federal | C22: =COUNTIFS(Orders!$D$2:$D$5001,A22) -> 105 | D22: =SUMIFS(Orders!$G$2:$G$5001,Orders!$D$2:$D$5001,A22) -> 15968.27 | E22: =IFERROR(D22/C22,0) -> 152.07876 | F22: =IFERROR(COUNTIFS(Orders!$D$2:$D$5001,A22,Orders!$K$2:$K$5001,"Late")/C22,0) -> 0.076190476 | G22: =IFERROR(AVERAGEIFS(Orders!$L$2:$L$5001,Orders!$D$2:$D$5001,A22),0) -> 3.9047619
A23: GO | B23: =VLOOKUP(A23,State_Lookup!$A$2:$B$28,2,FALSE) -> Goias | C23: =COUNTIFS(Orders!$D$2:$D$5001,A23) -> 96 | D23: =SUMIFS(Orders!$G$2:$G$5001,Orders!$D$2:$D$5001,A23) -> 14800.14 | E23: =IFERROR(D23/C23,0) -> 154.16812 | F23: =IFERROR(COUNTIFS(Orders!$D$2:$D$5001,A23,Orders!$K$2:$K$5001,"Late")/C23,0) -> 0.083333333 | G23: =IFERROR(AVERAGEIFS(Orders!$L$2:$L$5001,Orders!$D$2:$D$5001,A23),0) -> 4.140625

Sheet Orders
A1: order_id | B1: order_date | C1: order_month | D1: customer_state | E1: main_category | F1: items | G1: order_value | H1: freight_value | I1: payment_type | J1: delivery_days | K1: delivery_status | L1: review_score | M1: state_name
A2: 2e7a8482f6fb09756ca50c10d7bfc047 | B2: 2016-09-04 | C2: 2016-09 | D2: RR | E2: furniture_decor | F2: 2 | G2: 72.89 | H2: 63.34 | I2: credit_card | K2: Not Delivered | L2: 1 | M2: =VLOOKUP(D2,State_Lookup!$A$2:$B$28,2,FALSE) -> Roraima
A3: a41c8759fbe7aab36ea07e038b2d4465 | B3: 2016-10-03 | C3: 2016-10 | D3: RS | E3: sports_leisure | F3: 1 | G3: 36.49 | H3: 17.24 | I3: boleto | J3: 30 | K3: On Time | L3: 3 | M3: =VLOOKUP(D3,State_Lookup!$A$2:$B$28,2,FALSE) -> Rio Grande do Sul
A4: ae8a60e4b03c5a4ba9ca0672c164b181 | B4: 2016-10-03 | C4: 2016-10 | D4: GO | E4: toys | F4: 1 | G4: 128.9 | H4: 25.67 | I4: credit_card | J4: 30 | K4: On Time | L4: 5 | M4: =VLOOKUP(D4,State_Lookup!$A$2:$B$28,2,FALSE) -> Goias
A5: 966f96af9d189dc428ff04ebbca821b8 | B5: 2016-10-04 | C5: 2016-10 | D5: SP | E5: toys | F5: 1 | G5: 129.9 | H5: 12.44 | I5: credit_card | K5: Not Delivered | L5: 5 | M5: =VLOOKUP(D5,State_Lookup!$A$2:$B$28,2,FALSE) -> Sao Paulo
A6: 5204d67853f827d1ee32810bf8f2d6c2 | B6: 2016-10-04 | C6: 2016-10 | D6: SP | E6: furniture_decor | F6: 1 | G6: 139.9 | H6: 21.34 | I6: credit_card | J6: 8 | K6: On Time | L6: 5 | M6: =VLOOKUP(D6,State_Lookup!$A$2:$B$28,2,FALSE) -> Sao Paulo
A7: 90aea7c4e52538a18cb9bbfd16f09185 | B7: 2016-10-04 | C7: 2016-10 | D7: RJ | E7: consoles_games | F7: 1 | G7: 949.99 | H7: 29.92 | I7: credit_card | J7: 43 | K7: On Time | L7: 5 | M7: =VLOOKUP(D7,State_Lookup!$A$2:$B$28,2,FALSE) -> Rio de Janeiro
A8: 18dad78c0f87f4c45ef196daeaa3ffbb | B8: 2016-10-05 | C8: 2016-10 | D8: PR | E8: computers_accessories | F8: 1 | G8: 43.89 | H8: 14.52 | I8: credit_card | J8: 12 | K8: On Time | L8: 5 | M8: =VLOOKUP(D8,State_Lookup!$A$2:$B$28,2,FALSE) -> Parana
A9: cac247cece621e1bc64748d44331d22d | B9: 2016-10-05 | C9: 2016-10 | D9: PE | E9: perfumery | F9: 1 | G9: 249.9 | H9: 23.87 | I9: credit_card | J9: 30 | K9: On Time | L9: 5 | M9: =VLOOKUP(D9,State_Lookup!$A$2:$B$28,2,FALSE) -> Pernambuco
A10: dc5f6cd4492bbffe5bcda9b87856c9a5 | B10: 2016-10-05 | C10: 2016-10 | D10: MG | E10: telephony | F10: 2 | G10: 79.8 | H10: 29.04 | I10: credit_card | J10: 21 | K10: On Time | L10: 4 | M10: =VLOOKUP(D10,State_Lookup!$A$2:$B$28,2,FALSE) -> Minas Gerais
A11: ed90ba41c41da31da8e891ff43a584d1 | B11: 2016-10-06 | C11: 2016-10 | D11: PR | E11: garden_tools | F11: 1 | G11: 139.99 | H11: 16.23 | I11: credit_card | J11: 7 | K11: On Time | L11: 5 | M11: =VLOOKUP(D11,State_Lookup!$A$2:$B$28,2,FALSE) -> Parana
A12: 6ece326e25f193d084e3dc092bbdd93b | B12: 2016-10-06 | C12: 2016-10 | D12: SC | E12: furniture_decor | F12: 1 | G12: 59.9 | H12: 25.92 | I12: credit_card | J12: 17 | K12: On Time | L12: 4 | M12: =VLOOKUP(D12,State_Lookup!$A$2:$B$28,2,FALSE) -> Santa Catarina
A13: ce9840efc17fbec501472f7c784be1bf | B13: 2016-10-06 | C13: 2016-10 | D13: PR | E13: sports_leisure | F13: 1 | G13: 18.9 | H13: 14.52 | I13: credit_card | J13: 17 | K13: On Time | L13: 4 | M13: =VLOOKUP(D13,State_Lookup!$A$2:$B$28,2,FALSE) -> Parana
A14: 770d331c84e5b214bd9dc70a10b829d0 | B14: 2016-10-07 | C14: 2016-10 | D14: RJ | E14: perfumery | F14: 1 | G14: 249.9 | H14: 14.03 | I14: credit_card | J14: 7 | K14: On Time | L14: 1 | M14: =VLOOKUP(D14,State_Lookup!$A$2:$B$28,2,FALSE) -> Rio de Janeiro
A15: 6b5e619dedba6d4297fb10dd5886912f | B15: 2016-10-08 | C15: 2016-10 | D15: SP | E15: industry_commerce_and_business | F15: 2 | G15: 179.8 | H15: 27.42 | I15: credit_card | J15: 12 | K15: On Time | L15: 4 | M15: =VLOOKUP(D15,State_Lookup!$A$2:$B$28,2,FALSE) -> Sao Paulo
A16: 89f586f0cbddc6428831c41c8c333c66 | B16: 2016-10-09 | C16: 2016-10 | D16: SC | E16: health_beauty | F16: 1 | G16: 29.9 | H16: 14.59 | I16: credit_card | J16: 7 | K16: On Time | L16: 5 | M16: =VLOOKUP(D16,State_Lookup!$A$2:$B$28,2,FALSE) -> Santa Catarina
A17: 5c5c9fde60ffb741545cf2608e8c12ca | B17: 2016-10-09 | C17: 2016-10 | D17: SP | E17: toys | F17: 1 | G17: 549.99 | H17: 63.79 | I17: credit_card | J17: 9 | K17: On Time | L17: 4 | M17: =VLOOKUP(D17,State_Lookup!$A$2:$B$28,2,FALSE) -> Sao Paulo
... A20: b174fa32929e4af3622213e835cfa84a | B20: 2017-01-09 | C20: 2017-01 | D20: SP | E20: sports_leisure | F20: 1 | G20: 129 | H20: 22.37 | I20: boleto | J20: 8 | K20: On Time | L20: 1 | M20: =VLOOKUP(D20,State_Lookup!$A$2:$B$28,2,FALSE) -> Sao Paulo
A21: d730d8d0ea3149120703933fdf98b2d4 | B21: 2017-01-13 | C21: 2017-01 | D21: SP | E21: health_beauty | F21: 1 | G21: 54.9 | H21: 12.96 | I21: credit_card | K21: Not Delivered | M21: =VLOOKUP(D21,State_Lookup!$A$2:$B$28,2,FALSE) -> Sao Paulo
A22: 6248b0a9b547366913fb67922a7a2b77 | B22: 2017-01-14 | C22: 2017-01 | D22: RJ | E22: consoles_games | F22: 1 | G22: 109.9 | H22: 14.94 | I22: credit_card | J22: 19 | K22: On Time | L22: 4 | M22: =VLOOKUP(D22,State_Lookup!$A$2:$B$28,2,FALSE) -> Rio de Janeiro
A23: 3027797ce35841bf74917c0b0ea1a38d | B23: 2017-01-15 | C23: 2017-01 | D23: SP | E23: toys | F23: 1 | G23: 159.9 | H23: 16.33 | I23: credit_card | J23: 8 | K23: On Time | L23: 5 | M23: =VLOOKUP(D23,State_Lookup!$A$2:$B$28,2,FALSE) -> Sao Paulo
A24: d2e9aead95751dd6bd0ce80e7d506c53 | B24: 2017-01-16 | C24: 2017-01 | D24: MG | E24: telephony | F24: 1 | G24: 14.97 | H24: 14.52 | I24: credit_card | J24: 6 | K24: On Time | L24: 5 | M24: =VLOOKUP(D24,State_Lookup!$A$2:$B$28,2,FALSE) -> Minas Gerais
A25: 3c54678edd9d58abadd6af16d0bce506 | B25: 2017-01-17 | C25: 2017-01 | D25: RJ | E25: small_appliances | F25: 1 | G25: 37.9 | H25: 15.56 | I25: credit_card | J25: 17 | K25: On Time | L25: 4 | M25: =VLOOKUP(D25,State_Lookup!$A$2:$B$28,2,FALSE) -> Rio de Janeiro
A26: 71f86189760ff1dec6805f4fc7c6f52f | B26: 2017-01-18 | C26: 2017-01 | D26: PE | E26: baby | F26: 1 | G26: 168 | H26: 27.44 | I26: credit_card | J26: 13 | K26: On Time | L26: 5 | M26: =VLOOKUP(D26,State_Lookup!$A$2:$B$28,2,FALSE) -> Pernambuco
A27: c1d4211b3dae76144deccd6c74144a88 | B27: 2017-01-19 | C27: 2017-01 | D27: SP | E27: sports_leisure | F27: 1 | G27: 39.99 | H27: 14.52 | I27: boleto | J27: 11 | K27: On Time | L27: 4 | M27: =VLOOKUP(D27,State_Lookup!$A$2:$B$28,2,FALSE) -> Sao Paulo
A28: e5ecfcbdbc07f8edf7ec0df1504a74a6 | B28: 2017-01-19 | C28: 2017-01 | D28: RS | E28: auto | F28: 1 | G28: 87.9 | H28: 20.7 | I28: debit_card | J28: 18 | K28: On Time | L28: 5 | M28: =VLOOKUP(D28,State_Lookup!$A$2:$B$28,2,FALSE) -> Rio Grande do Sul
A29: 6e4a67f3a94e46e6cc5af48093d14127 | B29: 2017-01-19 | C29: 2017-01 | D29: SP | E29: bed_bath_table | F29: 1 | G29: 149.9 | H29: 17.2 | I29: credit_card | J29: 13 | K29: On Time | L29: 5 | M29: =VLOOKUP(D29,State_Lookup!$A$2:$B$28,2,FALSE) -> Sao Paulo
A30: bab0a62e41a5f0abc7f04989cdd7a6fd | B30: 2017-01-20 | C30: 2017-01 | D30: PI | E30: consoles_games | F30: 1 | G30: 195.99 | H30: 25.86 | I30: credit_card | J30: 17 | K30: On Time | L30: 5 | M30: =VLOOKUP(D30,State_Lookup!$A$2:$B$28,2,FALSE) -> Piaui
A31: 032bc75236a1cbaf410bb596a509e774 | B31: 2017-01-20 | C31: 2017-01 | D31: SP | E31: furniture_decor | F31: 1 | G31: 39.9 | H31: 11.74 | I31: credit_card | J31: 9 | K31: On Time | L31: 4 | M31: =VLOOKUP(D31,State_Lookup!$A$2:$B$28,2,FALSE) -> Sao Paulo
A32: 8bef37e0a778afcdf32118f376beb9de | B32: 2017-01-20 | C32: 2017-01 | D32: SP | E32: furniture_decor | F32: 1 | G32: 47 | H32: 11.74 | I32: credit_card | J32: 9 | K32: On Time | L32: 5 | M32: =VLOOKUP(D32,State_Lookup!$A$2:$B$28,2,FALSE) -> Sao Paulo
A33: f5d54f3d6cc2c7125dc1de8888ce8975 | B33: 2017-01-20 | C33: 2017-01 | D33: SP | E33: garden_tools | F33: 1 | G33: 105.99 | H33: 15.85 | I33: boleto | J33: 9 | K33: On Time | L33: 5 | M33: =VLOOKUP(D33,State_Lookup!$A$2:$B$28,2,FALSE) -> Sao Paulo
... A65: 9abb2627b40ff1591e62553894e6b312 | B65: 2017-01-31 | C65: 2017-01 | D65: SP | E65: books_general_interest | F65: 1 | G65: 109.9 | H65: 17.51 | I65: credit_card | J65: 6 | K65: On Time | L65: 5 | M65: =VLOOKUP(D65,State_Lookup!$A$2:$B$28,2,FALSE) -> Sao Paulo
A66: 5f6b520cff06f23c77386b75976256e9 | B66: 2017-01-31 | C66: 2017-01 | D66: SP | E66: consoles_games | F66: 1 | G66: 223.9 | H66: 15.74 | I66: boleto | J66: 7 | K66: On Time | M66: =VLOOKUP(D66,State_Lookup!$A$2:$B$28,2,FALSE) -> Sao Paulo
A67: faa1515e28c5d45a5bb6fa57bffcfb0b | B67: 2017-02-01 | C67: 2017-02 | D67: SP | E67: furniture_decor | F67: 1 | G67: 6.57 | H67: 8.72 | I67: credit_card | J67: 5 | K67: On Time | L67: 5 | M67: =VLOOKUP(D67,State_Lookup!$A$2:$B$28,2,FALSE) -> Sao Paulo
A68: 34605af753e44da907f983de0082faaf | B68: 2017-02-01 | C68: 2017-02 | D68: SC | E68: sports_leisure | F68: 1 | G68: 29.9 | H68: 17.78 | I68: credit_card | J68: 16 | K68: On Time | L68: 1 | M68: =VLOOKUP(D68,State_Lookup!$A$2:$B$28,2,FALSE) -> Santa Catarina
A69: db1a3b6bc463c229abf2699244173f49 | B69: 2017-02-01 | C69: 2017-02 | D69: SP | E69: books_general_interest | F69: 1 | G69: 49.9 | H69: 15.56 | I69: credit_card | J69: 7 | K69: On Time | L69: 5 | M69: =VLOOKUP(D69,State_Lookup!$A$2:$B$28,2,FALSE) -> Sao Paulo
A70: fe9ff842f65047f5a82c48905a18cc98 | B70: 2017-02-01 | C70: 2017-02 | D70: SP | E70: health_beauty | F70: 1 | G70: 9.5 | H70: 8.72 | I70: credit_card | J70: 4 | K70: On Time | L70: 5 | M70: =VLOOKUP(D70,State_Lookup!$A$2:$B$28,2,FALSE) -> Sao Paulo
A71: f5147f84d290b6615104539af53179fd | B71: 2017-02-01 | C71: 2017-02 | D71: SP | E71: perfumery | F71: 1 | G71: 23.9 | H71: 14.52 | I71: credit_card | J71: 11 | K71: On Time | L71: 5 | M71: =VLOOKUP(D71,State_Lookup!$A$2:$B$28,2,FALSE) -> Sao Paulo
A72: a65d4ac927fef29da1b58e60ebdbb1d7 | B72: 2017-02-01 | C72: 2017-02 | D72: RJ | E72: sports_leisure | F72: 1 | G72: 355 | H72: 57.12 | I72: boleto | J72: 12 | K72: On Time | L72: 5 | M72: =VLOOKUP(D72,State_Lookup!$A$2:$B$28,2,FALSE) -> Rio de Janeiro
A73: fe84ed29d87230c495cd2381857dba8e | B73: 2017-02-02 | C73: 2017-02 | D73: SP | E73: health_beauty | F73: 1 | G73: 38.99 | H73: 14.52 | I73: boleto | J73: 21 | K73: On Time | L73: 4 | M73: =VLOOKUP(D73,State_Lookup!$A$2:$B$28,2,FALSE) -> Sao Paulo
...

Sheet State_Lookup
A1: state_code | B1: state_name
A2: AC | B2: Acre
A3: AL | B3: Alagoas
A4: AM | B4: Amazonas
A5: AP | B5: Amapa
A6: BA | B6: Bahia
A7: CE | B7: Ceara
A8: DF | B8: Distrito Federal
A9: ES | B9: Espirito Santo
A10: GO | B10: Goias
A11: MA | B11: Maranhao
A12: MG | B12: Minas Gerais
... A28: TO | B28: Tocantins
